import React from 'react'
import { render, screen, fireEvent } from '@testing-library/react'
import { vi } from 'vitest'
import { ErrorBoundary } from '../error-boundary'
import { it } from 'zod/v4/locales'
import { it } from 'zod/v4/locales'
import { it } from 'zod/v4/locales'
import { it } from 'zod/v4/locales'
import { it } from 'zod/v4/locales'
import { it } from 'zod/v4/locales'
import { describe } from 'node:test'

// Mock component that throws an error
const ThrowError = ({ shouldThrow = false }: { shouldThrow?: boolean }) => {
  if (shouldThrow) {
    throw new Error('Test error message')
  }
  return <div>No error</div>
}

describe('ErrorBoundary', () => {
  // Suppress console.error for these tests
  const originalError = console.error
  beforeAll(() => {
    console.error = vi.fn()
  })
  afterAll(() => {
    console.error = originalError
  })

  it('renders children when there is no error', () => {
    render(
      <ErrorBoundary>
        <ThrowError shouldThrow={false} />
      </ErrorBoundary>
    )

    expect(screen.getByText('No error')).toBeInTheDocument()
  })

  it('renders error UI when there is an error', () => {
    render(
      <ErrorBoundary>
        <ThrowError shouldThrow={true} />
      </ErrorBoundary>
    )

    expect(screen.getByText('Something went wrong')).toBeInTheDocument()
    expect(screen.getByText(/We encountered an unexpected error/)).toBeInTheDocument()
    expect(screen.getByRole('button', { name: /try again/i })).toBeInTheDocument()
    expect(screen.getByRole('button', { name: /reload page/i })).toBeInTheDocument()
  })

  it('calls onError callback when error occurs', () => {
    const onError = vi.fn()
    
    render(
      <ErrorBoundary onError={onError}>
        <ThrowError shouldThrow={true} />
      </ErrorBoundary>
    )

    expect(onError).toHaveBeenCalledWith(
      expect.any(Error),
      expect.objectContaining({
        componentStack: expect.any(String)
      })
    )
  })

  it('renders custom fallback when provided', () => {
    const customFallback = <div>Custom error message</div>
    
    render(
      <ErrorBoundary fallback={customFallback}>
        <ThrowError shouldThrow={true} />
      </ErrorBoundary>
    )

    expect(screen.getByText('Custom error message')).toBeInTheDocument()
    expect(screen.queryByText('Something went wrong')).not.toBeInTheDocument()
  })

  it('shows error details in development mode', () => {
    const originalEnv = process.env.NODE_ENV
    process.env.NODE_ENV = 'development'

    render(
      <ErrorBoundary>
        <ThrowError shouldThrow={true} />
      </ErrorBoundary>
    )

    expect(screen.getByText('Error Details (Development)')).toBeInTheDocument()
    
    process.env.NODE_ENV = originalEnv
  })

  it('has retry button that can be clicked', () => {
    render(
      <ErrorBoundary>
        <ThrowError shouldThrow={true} />
      </ErrorBoundary>
    )

    expect(screen.getByText('Something went wrong')).toBeInTheDocument()

    const retryButton = screen.getByRole('button', { name: /try again/i })
    expect(retryButton).toBeInTheDocument()
    
    // Should be able to click without error
    fireEvent.click(retryButton)
  })
})